"""
Error Handling and Retry Logic Tests - TDD
오류 처리 및 재시도 로직 테스트 - TDD
"""

import pytest
import asyncio
import time
from unittest.mock import Mock, AsyncMock, patch
from datetime import datetime, timedelta
from typing import Dict, Any, List


class TestErrorHandling:
    """오류 처리 테스트"""
    
    @pytest.mark.asyncio
    async def test_api_error_handling(self):
        """API 오류 처리 테스트 - 아직 구현되지 않음 (RED)"""
        from src.error_handling.api_errors import APIErrorHandler
        
        handler = APIErrorHandler()
        
        # 다양한 API 오류 시나리오
        errors = [
            {"code": 400, "message": "Bad Request"},
            {"code": 401, "message": "Unauthorized"},
            {"code": 429, "message": "Too Many Requests"},
            {"code": 500, "message": "Internal Server Error"},
            {"code": 503, "message": "Service Unavailable"}
        ]
        
        for error in errors:
            response = await handler.handle_error(error["code"], error["message"])
            assert response is not None
            assert response["handled"] is True
            assert "retry_after" in response
            assert "should_retry" in response
    
    @pytest.mark.asyncio
    async def test_network_error_handling(self):
        """네트워크 오류 처리 테스트 - 아직 구현되지 않음 (RED)"""
        from src.error_handling.network_errors import NetworkErrorHandler
        
        handler = NetworkErrorHandler()
        
        # 네트워크 오류 시뮬레이션
        import aiohttp
        
        # 연결 타임아웃
        with pytest.raises(aiohttp.ClientConnectorError):
            await handler.handle_connection_error("example.com", 80)
        
        # 읽기 타임아웃
        result = await handler.handle_timeout_error("GET", "/api/data", timeout=5.0)
        assert result["retry_strategy"] == "exponential_backoff"
        assert result["max_retries"] == 3
    
    @pytest.mark.asyncio
    async def test_data_validation_error_handling(self):
        """데이터 유효성 검사 오류 처리 테스트 - 아직 구현되지 않음 (RED)"""
        from src.error_handling.validation_errors import ValidationErrorHandler
        
        handler = ValidationErrorHandler()
        
        # 잘못된 데이터 형식
        invalid_data = {
            "stock_code": "",  # 빈 종목 코드
            "volume": -100,    # 음수 거래량
            "price": "invalid" # 잘못된 가격 형식
        }
        
        errors = await handler.validate_and_handle(invalid_data)
        assert len(errors) == 3
        assert any(e["field"] == "stock_code" for e in errors)
        assert any(e["field"] == "volume" for e in errors)
        assert any(e["field"] == "price" for e in errors)
    
    @pytest.mark.asyncio
    async def test_graceful_degradation(self):
        """우아한 품질 저하 테스트 - 아직 구현되지 않음 (RED)"""
        from src.error_handling.graceful_degradation import GracefulDegradationHandler
        
        handler = GracefulDegradationHandler()
        
        # 메인 서비스 실패 시 폴백
        async def failing_service():
            raise Exception("Service unavailable")
        
        async def fallback_service():
            return {"data": "fallback_data", "degraded": True}
        
        result = await handler.with_fallback(failing_service, fallback_service)
        assert result["degraded"] is True
        assert result["data"] == "fallback_data"


class TestRetryLogic:
    """재시도 로직 테스트"""
    
    @pytest.mark.asyncio
    async def test_exponential_backoff_retry(self):
        """지수 백오프 재시도 테스트 - 아직 구현되지 않음 (RED)"""
        from src.error_handling.retry import ExponentialBackoffRetry
        
        retry = ExponentialBackoffRetry(
            max_retries=3,
            base_delay=0.1,
            max_delay=2.0,
            exponential_base=2
        )
        
        call_count = 0
        
        async def flaky_operation():
            nonlocal call_count
            call_count += 1
            if call_count < 3:
                raise Exception("Temporary failure")
            return "success"
        
        start_time = time.time()
        result = await retry.execute(flaky_operation)
        elapsed_time = time.time() - start_time
        
        assert result == "success"
        assert call_count == 3
        # 지수 백오프로 인한 지연 확인 (0.1 + 0.2 = 0.3초 이상)
        assert elapsed_time >= 0.3
    
    @pytest.mark.asyncio
    async def test_circuit_breaker_retry(self):
        """회로 차단기 재시도 테스트 - 아직 구현되지 않음 (RED)"""
        from src.error_handling.retry import CircuitBreakerRetry
        
        breaker = CircuitBreakerRetry(
            failure_threshold=3,
            recovery_timeout=1.0,
            half_open_requests=1
        )
        
        # 연속 실패로 회로 개방
        for _ in range(3):
            with pytest.raises(Exception):
                await breaker.execute(lambda: asyncio.sleep(0) or 1/0)
        
        # 회로가 개방된 상태에서는 즉시 실패
        with pytest.raises(Exception) as exc_info:
            await breaker.execute(lambda: asyncio.sleep(0))
        assert "Circuit breaker is open" in str(exc_info.value)
        
        # 복구 타임아웃 후 half-open 상태
        await asyncio.sleep(1.1)
        
        # 성공하면 회로 닫힘
        result = await breaker.execute(lambda: asyncio.sleep(0) or "success")
        assert result == "success"
        assert breaker.state == "closed"
    
    @pytest.mark.asyncio
    async def test_adaptive_retry(self):
        """적응형 재시도 테스트 - 아직 구현되지 않음 (RED)"""
        from src.error_handling.retry import AdaptiveRetry
        
        retry = AdaptiveRetry()
        
        # 성공률에 따라 재시도 정책 조정
        success_count = 0
        failure_count = 0
        
        async def variable_operation():
            nonlocal success_count, failure_count
            if success_count < 5:
                success_count += 1
                return "success"
            else:
                failure_count += 1
                if failure_count < 3:
                    raise Exception("Temporary failure")
                return "recovered"
        
        # 초기 성공으로 공격적인 재시도
        for _ in range(5):
            await retry.execute(variable_operation)
        
        assert retry.get_current_strategy() == "aggressive"
        
        # 실패 증가로 보수적인 재시도로 전환
        for _ in range(3):
            try:
                await retry.execute(variable_operation)
            except:
                pass
        
        assert retry.get_current_strategy() == "conservative"
    
    @pytest.mark.asyncio
    async def test_retry_with_jitter(self):
        """지터를 포함한 재시도 테스트 - 아직 구현되지 않음 (RED)"""
        from src.error_handling.retry import RetryWithJitter
        
        retry = RetryWithJitter(
            max_retries=5,
            base_delay=0.1,
            jitter_range=(0.0, 0.05)
        )
        
        delays = []
        
        async def track_delays():
            raise Exception("Always fails")
        
        # 모든 재시도의 지연 시간 추적
        original_sleep = asyncio.sleep
        
        async def mock_sleep(delay):
            delays.append(delay)
            await original_sleep(0.01)  # 실제로는 짧게
        
        with patch('asyncio.sleep', mock_sleep):
            with pytest.raises(Exception):
                await retry.execute(track_delays)
        
        # 지터로 인해 모든 지연이 다름
        assert len(set(delays)) == len(delays)
        # 모든 지연이 예상 범위 내
        for delay in delays:
            assert 0.1 <= delay <= 0.15


class TestErrorRecovery:
    """오류 복구 테스트"""
    
    @pytest.mark.asyncio
    async def test_state_recovery(self):
        """상태 복구 테스트 - 아직 구현되지 않음 (RED)"""
        from src.error_handling.recovery import StateRecoveryManager
        
        manager = StateRecoveryManager()
        
        # 상태 체크포인트 생성
        state = {"counter": 10, "items": ["a", "b", "c"]}
        checkpoint_id = await manager.create_checkpoint(state)
        
        # 상태 변경
        state["counter"] = 20
        state["items"].append("d")
        
        # 오류 발생 시 복구
        recovered_state = await manager.recover_from_checkpoint(checkpoint_id)
        assert recovered_state["counter"] == 10
        assert recovered_state["items"] == ["a", "b", "c"]
    
    @pytest.mark.asyncio
    async def test_transaction_rollback(self):
        """트랜잭션 롤백 테스트 - 아직 구현되지 않음 (RED)"""
        from src.error_handling.recovery import TransactionManager
        
        manager = TransactionManager()
        
        # 트랜잭션 시작
        tx = await manager.begin_transaction()
        
        try:
            # 작업 수행
            await tx.execute("UPDATE stocks SET volume = volume + 100")
            await tx.execute("UPDATE cache SET last_update = NOW()")
            
            # 오류 발생
            raise Exception("Something went wrong")
            
            await tx.commit()
        except Exception:
            # 롤백
            await tx.rollback()
        
        # 모든 변경사항이 롤백되었는지 확인
        assert tx.state == "rolled_back"
        assert len(tx.executed_operations) == 0
    
    @pytest.mark.asyncio
    async def test_partial_failure_recovery(self):
        """부분 실패 복구 테스트 - 아직 구현되지 않음 (RED)"""
        from src.error_handling.recovery import PartialFailureRecovery
        
        recovery = PartialFailureRecovery()
        
        # 여러 작업 중 일부만 실패
        tasks = [
            {"id": 1, "action": "process", "will_fail": False},
            {"id": 2, "action": "process", "will_fail": True},
            {"id": 3, "action": "process", "will_fail": False},
            {"id": 4, "action": "process", "will_fail": True},
        ]
        
        async def process_task(task):
            if task["will_fail"]:
                raise Exception(f"Task {task['id']} failed")
            return f"Task {task['id']} completed"
        
        results = await recovery.execute_with_partial_recovery(tasks, process_task)
        
        assert results["successful"] == 2
        assert results["failed"] == 2
        assert len(results["successful_tasks"]) == 2
        assert len(results["failed_tasks"]) == 2
        assert results["recovery_attempted"] is True


class TestErrorMonitoring:
    """오류 모니터링 테스트"""
    
    @pytest.mark.asyncio
    async def test_error_rate_monitoring(self):
        """오류율 모니터링 테스트 - 아직 구현되지 않음 (RED)"""
        from src.error_handling.monitoring import ErrorRateMonitor
        
        monitor = ErrorRateMonitor(window_size=60)  # 60초 윈도우
        
        # 정상 작업
        for _ in range(80):
            await monitor.record_success("api_call")
        
        # 오류 발생
        for _ in range(20):
            await monitor.record_error("api_call", "timeout")
        
        stats = await monitor.get_error_rate_stats("api_call")
        assert stats["error_rate"] == 0.2  # 20%
        assert stats["total_requests"] == 100
        assert stats["error_count"] == 20
        assert stats["success_count"] == 80
    
    @pytest.mark.asyncio
    async def test_error_pattern_detection(self):
        """오류 패턴 감지 테스트 - 아직 구현되지 않음 (RED)"""
        from src.error_handling.monitoring import ErrorPatternDetector
        
        detector = ErrorPatternDetector()
        
        # 반복적인 오류 패턴
        for i in range(10):
            await detector.record_error(
                error_type="timeout",
                endpoint="/api/stocks",
                timestamp=datetime.now() + timedelta(minutes=i*5)
            )
        
        patterns = await detector.detect_patterns()
        assert len(patterns) > 0
        assert patterns[0]["type"] == "periodic"
        assert patterns[0]["interval_minutes"] == 5
        assert patterns[0]["confidence"] > 0.8
    
    @pytest.mark.asyncio
    async def test_error_alerting(self):
        """오류 알림 테스트 - 아직 구현되지 않음 (RED)"""
        from src.error_handling.monitoring import ErrorAlertManager
        
        manager = ErrorAlertManager()
        
        # 알림 규칙 설정
        await manager.add_rule(
            name="high_error_rate",
            condition=lambda stats: stats["error_rate"] > 0.1,
            severity="critical"
        )
        
        # 오류 발생
        for _ in range(20):
            await manager.record_error("api_call", "server_error")
        
        for _ in range(80):
            await manager.record_success("api_call")
        
        # 알림 확인
        alerts = await manager.check_alerts()
        assert len(alerts) == 1
        assert alerts[0]["rule"] == "high_error_rate"
        assert alerts[0]["severity"] == "critical"
        assert alerts[0]["error_rate"] == 0.2


class TestIntegration:
    """통합 테스트"""
    
    @pytest.mark.asyncio
    async def test_end_to_end_error_handling(self):
        """종단간 오류 처리 테스트 - 아직 구현되지 않음 (RED)"""
        from src.error_handling.integration import ErrorHandlingSystem
        
        system = ErrorHandlingSystem()
        await system.initialize()
        
        # 실패하는 API 호출 시뮬레이션
        async def unreliable_api_call():
            import random
            if random.random() < 0.3:  # 30% 실패율
                raise Exception("API Error")
            return {"data": "success"}
        
        # 오류 처리 시스템을 통한 호출
        results = []
        for _ in range(10):
            try:
                result = await system.execute_with_handling(
                    unreliable_api_call,
                    retry_strategy="exponential",
                    fallback_value={"data": "fallback"}
                )
                results.append(result)
            except Exception as e:
                results.append({"error": str(e)})
        
        # 대부분의 요청이 성공 또는 폴백 처리됨
        successful = sum(1 for r in results if "data" in r)
        assert successful >= 8  # 80% 이상 성공
        
        # 오류 통계 확인
        stats = await system.get_error_stats()
        assert stats["total_retries"] > 0
        assert stats["fallback_count"] >= 0
        assert stats["circuit_breaker_activations"] >= 0